Workbook
Name MyList: 'E. Unit prices'!$A$2:$A$15

Sheet A. Introduction
A1: DEFINITIONS
A2: Trial preparation | B2: Steps 1 to 3 of the tricot approach. People meet to select test lines, select traits for evaluation, and discuss plans to establish trials. This includes trial design on ClimMob, test and deploy.
A3: Training field agents | B3: The research team will either travel to train field agents in trial regions or conduct centralised training sessions.
A4: Seed distribution | B4: Step 4 of the tricot approach. Farmers are trained in the tricot approach and in how to collect data. Each farmer receives a trial package of three technologies to be tested.
A5: Monitoring | B5: The research team will travel to collect agronomic evaluation data at different data collection moments from 30% of the trials. They get per diem.
A6: Data collection | B6: Extension/ Field agents collect data at specific crop-based moments (e.g., for beans, vegetative, reproductive, postharvest) and product evaluation from all blocks assigned in a particular administrative unit.
A7: Yield measurement | B7: The research team will travel to support harvesting, and yield estimation at harvest from 30% of the trials. They get per diem.
A8: Food product evaluation | B8: People will travel to organise consumer testing of crop products (e.g., fresh boiled cassava, flour-based cassava paste). They get per diem.
A9: Data analysis | B9: One person cleans and analyses data received from all blocks.
A10: Feedback | B10: Every farmer is informed about the results of the trial regarding their farm and shares their view on the experience.
A11: Fixed Cost | B11: Costs that stay the same regardless of how many farmers are involved in the process (E.g. coordinator time, training materials etc.).
A12: Variable Cost | B12: Costs that increase with scale (e.g. seeds, transport per farmer).
A13: Avoidable Cost | B13: A cost that might be reduced in future (e.g. travel if replaced by remote support).
A14: Scenario Analysis | B14: A way to test how much you could save by removing or reducing costs.
A16: TRICOT TRIAL PHASES
A17: Step 1: Preparation | B17: Researchers define a set of comparable technology options to test. For example, they decide to compare crop varieties with each other, or different fertilizer types, or irrigation technologies. They will provide the necessary materials (inputs or other) to project implementers (organizations that will reach farmers). Typically, about 8-12 technology options (comparable items) are included in the trial to be tested.
A18: Step 2: Design | B18: The implementing organization uses the ClimMob (climmob.net) free online software to design the project. This digital platform has been specifically created to manage tricot projects, from designing the experiment to data collection and analysis. The use of the digital platform streamlines the process. ClimMob offers the following benefits: 1. ClimMob helps to avoid mistakes by introducing QR codes and electronic forms; 2. ClimMob provides a dashboard to monitor progress; 3. ClimMob reduces or eliminates the effort spent on digitalizing data collected on paper; 4. ClimMob creates automatic reports with analytical results, avoiding the usual lengthy process of data cleaning and analysis; 5. ClimMob provides clean, formatted data that can be easily downloaded for further analysis with existing tools, for example, combining with weather data.
A19: Step 3: Recruitment | B19: The implementers recruit dedicated farmers interested in improving their farming through the use of new technologies.
A20: Step 4: Distribution | B20: Farmers are trained in the tricot approach and on how to collect data. Each farmer receives a trial package of three technologies to be tested.
A21: Step 5: Execution | B21: Farmers use their trial packages to apply the new technology options separately, on small plots next to each other, in a mini-trial on their own farm. To avoid any bias, they are not aware of the names of the crop varieties or other technology options they are testing. These are revealed to them only after the data has been collected
A22: Step 6: Observation | B22: Every farmer is responsible for their own trial and makes various easy observations about their three options over the course of the season. For example: Which variety had the highest or the lowest yield? The farmers record these observations on an observation card.
A23: Step 7: Compilation | B23: The local designated field agents collect and compile the observation data from the tricot farmers, either in person or by phone. They record the information digitally and send them on to the implementing organization. For this, they can use the free ‘ODK Collect’ smartphone app, which is connected to the ClimMob software
A24: Step 8: Analysis | B24: The implementers compile and analyze the data from the trials, using the ClimMob online software, to identify which technology options showed the best performance and under which conditions.
A25: Step 9: Feedback | B25: The implementers provide feedback to every participating farmer: the names of their three technology options, which options were most suited to their farm (out of the three options tried by them and out of all the options tried by farmers throughout the project), and where to obtain them.
A26: Step 10: Evaluation | B26: Tricot is an iterative process: after every project cycle, researchers, implementers and farmers collaboratively evaluate how the process may be improved in the next cycle.
A29: Hours of work includes hours spent on meetings, designing, testing and deploying the project on ClimMob and the registration of the participants.
A30: Hours of travel includes hours spent transferring from one place to another at any
A31: All costs are expressed in USD

Sheet B. Trial dimensions
A1: Dimension | B1: Value
A2: Country
A3: Crop
A4: Breeding institution
A5: Product profile
A6: Trial start date (dd/mm/yyyy)
A7: Trial end date (dd/mm/yyyy)
A8: Trial duration (days after planting) | B8: =B7-B6 -> 0
A9: No. farmers (participants)
A10: No. varieties
A11: Units planting material per variety per plot
A12: No. monitoring visits - research
A13: No. monitoring visits - extension
A14: No. plots per farm | B14: 3
A15: Total no. of plots per variety | B15: =(B9*B14)/B10 -> #DIV/0!
A16: Units planting material needed per variety | B16: =B15*B11 -> #DIV/0!
A17: Total units of planting material per trial | B17: =B16*B10 -> #DIV/0!
A18: Working days per month
A19: Working hours per day
A20: Per diem rate
A21: Exchange rate (USD)
A23: Note
A24: *Working days per month range from 20 to 22, depending a country's public holidays
A25: * Per diem rate is a flat rate (average of per diem for all job roles) to be applied to all destinations and to all people involved in travel

Sheet C. Seed required - RTB
A1: Dimension | B1: Unit | C1: Value
A2: Cuttings per 100kg bag | B2: number
A3: Quantity of cuttings required | B3: bags | C3: ='B. Trial dimensions'!B17/C2 -> #DIV/0!
A4: Estimated stem/vine/tuber yield | B4: bags/ acre
A5: Seed production area for tricot | B5: acre | C5: =C3/C4 -> #DIV/0!
A6: Seed rate | B6: bags/ acre

Sheet D. Seed multiplication - RTB
A1: Item | B1: Unit | C1: Quantity | D1: Unit Cost (USD) | E1: TOTAL COSTS (USD) | F1: Comments
A2: Materials/ inputs
A3: Planting material (basic seed) | B3: Bag | C3: ='C. Seed required - RTB'!C5*'C. Seed required - RTB'!C6 -> #DIV/0! | E3: =C3*D3 -> #DIV/0!
A4: Herbicides | B4: Litre | E4: =C4*D4 -> 0
A5: Plastic woven sacs holding 100 kg | B5: Bag | E5: =C5*D5 -> 0
A6: Transport for delivery of planting material | B6: Bag | C6: ='C. Seed required - RTB'!C5*'C. Seed required - RTB'!C6 -> #DIV/0! | E6: =C6*D6 -> #DIV/0!
A7: Gap filling material | B7: Bag | C7: =15%*C3 -> #DIV/0! | E7: =C7*D7 -> #DIV/0!
A8: Labour
A9: 1st ploughing | B9: Acre | C9: ='C. Seed required - RTB'!$C$5 -> #DIV/0! | E9: =C9*D9 -> #DIV/0!
A10: 2nd ploughing | B10: Acre | C10: ='C. Seed required - RTB'!$C$5 -> #DIV/0! | E10: =C10*D10 -> #DIV/0!
A11: Disc harrowing | B11: Acre | C11: ='C. Seed required - RTB'!$C$5 -> #DIV/0! | E11: =C11*D11 -> #DIV/0!
A12: Field marking | B12: Acre | C12: ='C. Seed required - RTB'!$C$5 -> #DIV/0! | E12: =C12*D12 -> #DIV/0!
A13: Planting labor | B13: Acre | C13: ='C. Seed required - RTB'!$C$5 -> #DIV/0! | E13: =C13*D13 -> #DIV/0!
A14: Herbicide application | B14: Acre | C14: ='C. Seed required - RTB'!$C$5 -> #DIV/0! | E14: =C14*D14 -> #DIV/0!
A15: Gap filling | B15: Acre | C15: ='C. Seed required - RTB'!$C$5 -> #DIV/0! | E15: =C15*D15 -> #DIV/0!
A16: Weeding (4 times at interval of 1 - 1.5 months) | B16: Acre | C16: ='C. Seed required - RTB'!$C$5 -> #DIV/0! | E16: =C16*D16 -> #DIV/0!
A17: 1st weeding | B17: Acre | C17: ='C. Seed required - RTB'!$C$5 -> #DIV/0! | E17: =C17*D17 -> #DIV/0!
A18: 2nd weeding | B18: Acre | C18: ='C. Seed required - RTB'!$C$5 -> #DIV/0! | E18: =C18*D18 -> #DIV/0!
A19: 3rd weeding | B19: Acre | C19: ='C. Seed required - RTB'!$C$5 -> #DIV/0! | E19: =C19*D19 -> #DIV/0!
A20: 4th weeding | B20: Acre | C20: ='C. Seed required - RTB'!$C$5 -> #DIV/0! | E20: =C20*D20 -> #DIV/0!
... A25: 4th Slash weeding | B25: Acre | C25: ='C. Seed required - RTB'!$C$5 -> #DIV/0! | E25: =C25*D25 -> #DIV/0!
A26: Monitoring and supervision | B26: Visit | D26: =[1]Trial_dimensions!B19 -> 20 | E26: =C26*D26 -> 0
A27: Harvesting labor (cutting, bundling & labelling) | B27: Bags | E27: =C27*D27 -> 0
A28: TOTAL SEED COST | E28: =SUM(E3:E27) -> #DIV/0!
A29: TOTAL SEED PRODUCED (CUTTINGS) | E29: ='C. Seed required - RTB'!C4*'C. Seed required - RTB'!C5*'C. Seed required - RTB'!C2 -> #DIV/0!
A30: COST OF SEED PER CUTTING | E30: =E28/E29 -> #DIV/0!
A32: Note
A33: *Cost of seed per unit: Total cost divided by the quantity produced and used for tricot trials
A34: *Unit for seeds for RTB crops vary; cassava: stakes/cuttins, Sweetpotato: Cuttings, and Banana: Suckers or plantlets

Sheet E. Unit prices
A1: Item | B1: Type | C1: Units | D1: Gross_price | E1: Gross_quantity | F1: Unit_price | G1: Comments
A2: [Add if needed] | D2: ='D. Seed multiplication - RTB'!E28 -> #DIV/0! | E2: ='D. Seed multiplication - RTB'!E29 -> #DIV/0! | F2: =IFERROR(D2/E2,"")
A3: [Add if needed] | F3: =IFERROR(D3/E3,"")
A4: [Add if needed] | F4: =IFERROR(D4/E4,"")
A5: [Add if needed] | F5: =IFERROR(D5/E5,"")
A6: [Add if needed] | F6: =IFERROR(D6/E6,"")
A7: [Add if needed] | F7: =IFERROR(D7/E7,"")
A8: [Add if needed] | F8: =IFERROR(D8/E8,"")
A9: [Add if needed] | F9: =IFERROR(D9/E9,"")
A10: [Add if needed] | F10: =IFERROR(D10/E10,"")
A11: [Add if needed] | F11: =IFERROR(D11/E11,"")
A12: [Add if needed] | F12: =IFERROR(D12/E12,"")
A13: [Add if needed] | F13: =IFERROR(D13/E13,"")
A14: [Add if needed] | F14: =IFERROR(D14/E14,"")
... A23: [Add if needed] | F23: =IFERROR(D23/E23,"")
A24: Communication bundle | B24: Communication | C24: Bundle | D24: 2.96 | E24: 1 | F24: =IFERROR(D24/E24,"") -> 2.96 | G24: See instructions on the Call_costs worksheet to obtain the costs for the Mobile data and voice low-consumption basket
A25: Travel reimbursement rate | B25: Transport | C25: $/ km | D25: 0.28 | E25: 1 | F25: =IFERROR(D25/E25,"") -> 0.28 | G25: Rate caters for cost of fuel and other operation and maintenance costs, such as insurance, lubricants etc.
A27: * Snacks and lunch for each participant can be estimated from proportion of food in poverty line [(Cost of Food Basket)/(Total Poverty Line)]
A28: * For example, if the cost of food basket is $0.87 and the poverty line is $1.04 per day/person, the proportion of food in poverty line is 0.87/2.15, which equals to 0.4 or 40%.
A29: * This implies the daily cost of food is 0.4*$2.15=$0.86
A30: *Check for information on poverty line at: | B30: http://www.worldbank.org/poverty
A31: *Rate for travel by private vehicle for each country can be accessed at: | D31: https://hr.un.org/node/53991
A32: *Adjust the rate for inflation and add it to the cost per km. Use the "Inflation Calculator" available at | F32: https://www.usinflationcalculator.com/

Sheet F. Material costs
A1: Item | B1: Units_per_block | C1: Units_per_trial | D1: Cost_per_trial
A2: {=_xlfn._xlws.FILTER('E. Unit prices'!A2:A23, 'E. Unit prices'!A2:A23<>"")} -> [Add if needed] | B2: ='B. Trial dimensions'!B11*'B. Trial dimensions'!B14 -> 0 | C2: =$B2*'B. Trial dimensions'!$B$9 -> 0 | D2: =IF(ISNUMBER('E. Unit prices'!F2), $C2*'E. Unit prices'!F2, 0) -> 0
A3: [Add if needed] | C3: =$B3*'B. Trial dimensions'!$B$9 -> 0 | D3: =IF(ISNUMBER('E. Unit prices'!F3), $C3*'E. Unit prices'!F3, 0) -> 0
A4: [Add if needed] | C4: =$B4*'B. Trial dimensions'!$B$9 -> 0 | D4: =IF(ISNUMBER('E. Unit prices'!F4), $C4*'E. Unit prices'!F4, 0) -> 0
A5: [Add if needed] | C5: =$B5*'B. Trial dimensions'!$B$9 -> 0 | D5: =IF(ISNUMBER('E. Unit prices'!F5), $C5*'E. Unit prices'!F5, 0) -> 0
A6: [Add if needed] | C6: =$B6*'B. Trial dimensions'!$B$9 -> 0 | D6: =IF(ISNUMBER('E. Unit prices'!F6), $C6*'E. Unit prices'!F6, 0) -> 0
A7: [Add if needed] | C7: =$B7*'B. Trial dimensions'!$B$9 -> 0 | D7: =IF(ISNUMBER('E. Unit prices'!F7), $C7*'E. Unit prices'!F7, 0) -> 0
A8: [Add if needed] | C8: =$B8*'B. Trial dimensions'!$B$9 -> 0 | D8: =IF(ISNUMBER('E. Unit prices'!F8), $C8*'E. Unit prices'!F8, 0) -> 0
A9: [Add if needed] | C9: =$B9*'B. Trial dimensions'!$B$9 -> 0 | D9: =IF(ISNUMBER('E. Unit prices'!F9), $C9*'E. Unit prices'!F9, 0) -> 0
A10: [Add if needed] | C10: =$B10*'B. Trial dimensions'!$B$9 -> 0 | D10: =IF(ISNUMBER('E. Unit prices'!F10), $C10*'E. Unit prices'!F10, 0) -> 0 | H10: =16200/500 -> 32.4
A11: [Add if needed] | C11: =$B11*'B. Trial dimensions'!$B$9 -> 0 | D11: =IF(ISNUMBER('E. Unit prices'!F11), $C11*'E. Unit prices'!F11, 0) -> 0
A12: [Add if needed] | C12: =$B12*'B. Trial dimensions'!$B$9 -> 0 | D12: =IF(ISNUMBER('E. Unit prices'!F12), $C12*'E. Unit prices'!F12, 0) -> 0
A13: [Add if needed] | C13: =$B13*'B. Trial dimensions'!$B$9 -> 0 | D13: =IF(ISNUMBER('E. Unit prices'!F13), $C13*'E. Unit prices'!F13, 0) -> 0
A14: [Add if needed] | C14: =$B14*'B. Trial dimensions'!$B$9 -> 0 | D14: =IF(ISNUMBER('E. Unit prices'!F16), $C14*'E. Unit prices'!F16, 0) -> 0
A15: [Add if needed] | C15: =$B15*'B. Trial dimensions'!$B$9 -> 0 | D15: =IF(ISNUMBER('E. Unit prices'!F17), $C15*'E. Unit prices'!F17, 0) -> 0
A16: [Add if needed] | C16: =$B16*'B. Trial dimensions'!$B$9 -> 0 | D16: =IF(ISNUMBER('E. Unit prices'!F18), $C16*'E. Unit prices'!F18, 0) -> 0
A17: [Add if needed] | C17: =$B17*'B. Trial dimensions'!$B$9 -> 0 | D17: =IF(ISNUMBER('E. Unit prices'!F19), $C17*'E. Unit prices'!F19, 0) -> 0
A18: [Add if needed] | C18: =$B18*'B. Trial dimensions'!$B$9 -> 0 | D18: =IF(ISNUMBER('E. Unit prices'!F20), $C18*'E. Unit prices'!F20, 0) -> 0
A19: [Add if needed] | C19: =$B19*'B. Trial dimensions'!$B$9 -> 0 | D19: =IF(ISNUMBER('E. Unit prices'!F21), $C19*'E. Unit prices'!F21, 0) -> 0
A20: [Add if needed] | C20: =$B20*'B. Trial dimensions'!$B$9 -> 0 | D20: =IF(ISNUMBER('E. Unit prices'!F22), $C20*'E. Unit prices'!F22, 0) -> 0
A21: [Add if needed] | C21: =$B21*'B. Trial dimensions'!$B$9 -> 0 | D21: =IF(ISNUMBER('E. Unit prices'!F23), $C21*'E. Unit prices'!F23, 0) -> 0
A22: [Add if needed] | C22: =$B22*'B. Trial dimensions'!$B$9 -> 0 | D22: =IF(ISNUMBER('E. Unit prices'!#REF!), $C22*'E. Unit prices'!#REF!, 0) -> 0
A23: [Add if needed] | C23: =$B23*'B. Trial dimensions'!$B$9 -> 0 | D23: =IF(ISNUMBER('E. Unit prices'!F25), $C23*'E. Unit prices'!F25, 0) -> 0
A24: TOTAL PER TRIAL | D24: =SUM(D2:D23) -> 0
A25: TOTAL PER BLOCK | D25: =D24/'B. Trial dimensions'!B9 -> #DIV/0!

Sheet Fuel_actual
A1: Fuel_type | B1: Units | C1: Gross_price | D1: Fuel efficiency (km/liter) | E1: Unit_price | F1: Maintenance schedule in Km | G1: Avg. operation & maintenance cost | H1: Operation &Maintenance cost per Km | I1: Comments
A2: Diesel (car) | B2: km | C2: 1.29 | D2: 10 | E2: =C2/D2 -> 0.129 | F2: 50000 | G2: 500 | H2: =G2/F2 -> 0.01 | I2: Driver delivers seed in central location by sub-county. The cost of diesel is $1.29/ Litre, Each litre covers 10km (fuel economy: 10Km/Litre)
A3: Petrol (car) | B3: km | C3: 1.44 | D3: 9 | E3: =C3/D3 -> 0.16 | F3: 50000 | G3: 500 | H3: =G3/F3 -> 0.01 | I3: Cost of petrol is $1.44/ Litre, Each litre covers 22.73 km for a motorcycle
A4: Petrol (motorcycle) | B4: km | C4: 1.44 | D4: 22 | E4: =C4/D4 -> 0.065454545 | F4: 5000 | G4: 100 | H4: =G4/F4 -> 0.02 | I4: Cost of petrol is $1.44/ Litre, Each litre covers 22.73 km for a motorcycle
A7: *Adjust fuel efficiency for Road Quality index (RQI) or International Roughness index (IRI)
A8: * Rule of thumb: You can reduce your target km/liter by 8-18% when driving on rough roads
A9: https://hr.un.org/node/53991
A10: Multiply this with inflation to get km price. Let's not complicate with road quality and maintenance (or other costs, such as insurance)

Sheet G. Wages
A1: Job role | B1: Monthly salary | C1: Daily rate | D1: Hourly rate | E1: Per diem | F1: Travel allowance
A2: [Add if needed] | C2: =B2/'B. Trial dimensions'!$B$18 -> #DIV/0! | D2: =C2/'B. Trial dimensions'!$B$19 -> #DIV/0!
A3: [Add if needed] | C3: =B3/'B. Trial dimensions'!$B$18 -> #DIV/0! | D3: =C3/'B. Trial dimensions'!$B$19 -> #DIV/0!
A4: [Add if needed] | C4: =B4/'B. Trial dimensions'!$B$18 -> #DIV/0! | D4: =C4/'B. Trial dimensions'!$B$19 -> #DIV/0!
A5: [Add if needed] | C5: =B5/'B. Trial dimensions'!$B$18 -> #DIV/0! | D5: =C5/'B. Trial dimensions'!$B$19 -> #DIV/0!
A6: [Add if needed] | C6: =B6/'B. Trial dimensions'!$B$18 -> #DIV/0! | D6: =C6/'B. Trial dimensions'!$B$19 -> #DIV/0!
A7: [Add if needed] | C7: =B7/'B. Trial dimensions'!$B$18 -> #DIV/0! | D7: =C7/'B. Trial dimensions'!$B$19 -> #DIV/0!
A8: [Add if needed] | C8: =B8/'B. Trial dimensions'!$B$18 -> #DIV/0! | D8: =C8/'B. Trial dimensions'!$B$19 -> #DIV/0!
A9: [Add if needed] | C9: =B9/'B. Trial dimensions'!$B$18 -> #DIV/0! | D9: =C9/'B. Trial dimensions'!$B$19 -> #DIV/0!
A10: [Add if needed] | C10: =B10/'B. Trial dimensions'!$B$18 -> #DIV/0! | D10: =C10/'B. Trial dimensions'!$B$19 -> #DIV/0!
A11: [Add if needed] | C11: =B11/'B. Trial dimensions'!$B$18 -> #DIV/0! | D11: =C11/'B. Trial dimensions'!$B$19 -> #DIV/0!
A12: [Add if needed] | C12: =B12/'B. Trial dimensions'!$B$18 -> #DIV/0! | D12: =C12/'B. Trial dimensions'!$B$19 -> #DIV/0!
A13: [Add if needed] | C13: =B13/'B. Trial dimensions'!$B$18 -> #DIV/0! | D13: =C13/'B. Trial dimensions'!$B$19 -> #DIV/0!
... A15: [Add if needed] | C15: =B15/'B. Trial dimensions'!$B$18 -> #DIV/0! | D15: =C15/'B. Trial dimensions'!$B$19 -> #DIV/0!

Sheet H. Labour time
B1: Hours of work needed per activity, per job role
A2: Job role | B2: Trial preparation | C2: Training field agents | D2: Seed distribution | E2: Total number of farm visits * | F2: Number of hours per visit | G2: Monitoring ** | H2: Data collection | I2: Yield measurement | J2: Product Evaluation | K2: Farmer Feedback | L2: TOTAL HOURS | M2: TOTAL DAYS | N2: Comments
A3: {=_xlfn._xlws.FILTER('G. Wages'!A2:A15, 'G. Wages'!A2:A15<>"")} -> [Add if needed] | G3: =IF(E3<='B. Trial dimensions'!$B$12*'B. Trial dimensions'!$B$9,E3*F3,"Number is too high") -> 0 | L3: =B3+C3+D3+G3+H3+I3+J3+K3 -> 0 | M3: =L3/'B. Trial dimensions'!$B$19 -> #DIV/0!
A4: [Add if needed] | G4: =IF(E4<='B. Trial dimensions'!$B$12*'B. Trial dimensions'!$B$9,E4*F4,"Number is too high") -> 0 | L4: =B4+C4+D4+G4+H4+I4+J4+K4 -> 0 | M4: =L4/'B. Trial dimensions'!$B$19 -> #DIV/0!
A5: [Add if needed] | G5: =IF(E5<='B. Trial dimensions'!$B$12*'B. Trial dimensions'!$B$9,E5*F5,"Number is too high") -> 0 | L5: =B5+C5+D5+G5+H5+I5+J5+K5 -> 0 | M5: =L5/'B. Trial dimensions'!$B$19 -> #DIV/0!
A6: [Add if needed] | G6: =IF(E6<='B. Trial dimensions'!$B$12*'B. Trial dimensions'!$B$9,E6*F6,"Number is too high") -> 0 | L6: =B6+C6+D6+G6+H6+I6+J6+K6 -> 0 | M6: =L6/'B. Trial dimensions'!$B$19 -> #DIV/0!
A7: [Add if needed] | G7: =IF(E7<='B. Trial dimensions'!$B$12*'B. Trial dimensions'!$B$9,E7*F7,"Number is too high") -> 0 | L7: =B7+C7+D7+G7+H7+I7+J7+K7 -> 0 | M7: =L7/'B. Trial dimensions'!$B$19 -> #DIV/0!
A8: [Add if needed] | G8: =IF(E8<='B. Trial dimensions'!$B$12*'B. Trial dimensions'!$B$9,E8*F8,"Number is too high") -> 0 | L8: =B8+C8+D8+G8+H8+I8+J8+K8 -> 0 | M8: =L8/'B. Trial dimensions'!$B$19 -> #DIV/0!
A9: [Add if needed] | G9: =IF(E9<='B. Trial dimensions'!$B$13*'B. Trial dimensions'!$B$9,E9*F9,"Number is too high") -> 0 | L9: =B9+C9+D9+G9+H9+I9+J9+K9 -> 0 | M9: =L9/'B. Trial dimensions'!$B$19 -> #DIV/0!
A10: [Add if needed] | G10: =IF(E10<='B. Trial dimensions'!$B$13*'B. Trial dimensions'!$B$9,E10*F10,"Number is too high") -> 0 | L10: =B10+C10+D10+G10+H10+I10+J10+K10 -> 0 | M10: =L10/'B. Trial dimensions'!$B$19 -> #DIV/0!
A11: [Add if needed] | G11: =IF(E11<='B. Trial dimensions'!$B$13*'B. Trial dimensions'!$B$9,E11*F11,"Number is too high") -> 0 | L11: =B11+C11+D11+G11+H11+I11+J11+K11 -> 0 | M11: =L11/'B. Trial dimensions'!$B$19 -> #DIV/0!
A12: [Add if needed] | G12: =IF(E12<='B. Trial dimensions'!$B$13*'B. Trial dimensions'!$B$9,E12*F12,"Number is too high") -> 0 | L12: =B12+C12+D12+G12+H12+I12+J12+K12 -> 0 | M12: =L12/'B. Trial dimensions'!$B$19 -> #DIV/0!
A13: [Add if needed] | G13: =IF(E13<='B. Trial dimensions'!$B$13*'B. Trial dimensions'!$B$9,E13*F13,"Number is too high") -> 0 | L13: =B13+C13+D13+G13+H13+I13+J13+K13 -> 0 | M13: =L13/'B. Trial dimensions'!$B$19 -> #DIV/0!
A14: [Add if needed] | G14: =IF(E14<='B. Trial dimensions'!$B$13*'B. Trial dimensions'!$B$9,E14*F14,"Number is too high") -> 0 | L14: =B14+C14+D14+G14+H14+I14+J14+K14 -> 0 | M14: =L14/'B. Trial dimensions'!$B$19 -> #DIV/0!
A15: [Add if needed] | G15: =IF(E15<='B. Trial dimensions'!$B$13*'B. Trial dimensions'!$B$9,E15*F15,"Number is too high") -> 0 | L15: =B15+C15+D15+G15+H15+I15+J15+K15 -> 0 | M15: =L15/'B. Trial dimensions'!$B$19 -> #DIV/0!
A16: [Add if needed] | G16: =IF(E16<='B. Trial dimensions'!$B$13*'B. Trial dimensions'!$B$9,E16*F16,"Number is too high") -> 0 | L16: =B16+C16+D16+G16+H16+I16+J16+K16 -> 0 | M16: =L16/'B. Trial dimensions'!$B$19 -> #DIV/0!
A17: TOTAL PER STAGE (HOURS) | B17: =SUM(B3:B16) -> 0 | C17: =SUM(C3:C16) -> 0 | D17: =SUM(D3:D16) -> 0 | E17: =SUM(E3:E16) -> 0 | F17: =SUM(F3:F16) -> 0 | G17: =SUM(G3:G16) -> 0 | H17: =SUM(H3:H16) -> 0 | I17: =SUM(I3:I16) -> 0 | ... M17: =SUM(M3:M16) -> #DIV/0!
A18: TOTAL PER STAGE (DAYS) | B18: =B17/'B. Trial dimensions'!$B$19 -> #DIV/0! | C18: =C17/'B. Trial dimensions'!$B$19 -> #DIV/0! | D18: =D17/'B. Trial dimensions'!$B$19 -> #DIV/0! | E18: =E17/'B. Trial dimensions'!$B$19 -> #DIV/0! | F18: =F17/'B. Trial dimensions'!$B$19 -> #DIV/0! | G18: =G17/'B. Trial dimensions'!$B$19 -> #DIV/0! | H18: =H17/'B. Trial dimensions'!$B$19 -> #DIV/0! | I18: =I17/'B. Trial dimensions'!$B$19 -> #DIV/0! | ... L18: =L17/'B. Trial dimensions'!$B$19 -> #DIV/0!
A20: * The number of farm visits should be calculated as follows: Total number of farms visited x Number of follow-up visits
A21: * Hours of work include time spent while traveling

Sheet I. Labour costs
A1: Labour cost per activity, per job role
A2: Job role | B2: Trial preparation | C2: Training field agents | D2: Seed distribution | E2: Monitoring * | F2: Data collection | G2: Yield measurement | H2: Product Evaluation | I2: Farmer Feedback | J2: TOTAL SALARY
A3: {=_xlfn._xlws.FILTER('G. Wages'!A2:A15, 'G. Wages'!A2:A15<> "")} -> [Add if needed] | B3: ='H. Labour time'!B3*'G. Wages'!$D2 -> #DIV/0! | C3: ='H. Labour time'!C3*'G. Wages'!$D2 -> #DIV/0! | D3: ='H. Labour time'!D3*'G. Wages'!$D2 -> #DIV/0! | E3: ='H. Labour time'!G3*'G. Wages'!$D2 -> #DIV/0! | F3: ='H. Labour time'!H3*'G. Wages'!$D2 -> #DIV/0! | G3: ='H. Labour time'!I3*'G. Wages'!$D2 -> #DIV/0! | H3: ='H. Labour time'!J3*'G. Wages'!$D2 -> #DIV/0! | I3: ='H. Labour time'!K3*'G. Wages'!$D2 -> #DIV/0! | J3: =SUM(B3:I3) -> #DIV/0!
A4: [Add if needed] | B4: ='H. Labour time'!B4*'G. Wages'!$D3 -> #DIV/0! | C4: ='H. Labour time'!C4*'G. Wages'!$D3 -> #DIV/0! | D4: ='H. Labour time'!D4*'G. Wages'!$D3 -> #DIV/0! | E4: ='H. Labour time'!G4*'G. Wages'!$D3 -> #DIV/0! | F4: ='H. Labour time'!H4*'G. Wages'!$D3 -> #DIV/0! | G4: ='H. Labour time'!I4*'G. Wages'!$D3 -> #DIV/0! | H4: ='H. Labour time'!J4*'G. Wages'!$D3 -> #DIV/0! | I4: ='H. Labour time'!K4*'G. Wages'!$D3 -> #DIV/0! | J4: =SUM(B4:I4) -> #DIV/0!
A5: [Add if needed] | B5: ='H. Labour time'!B5*'G. Wages'!$D4 -> #DIV/0! | C5: ='H. Labour time'!C5*'G. Wages'!$D4 -> #DIV/0! | D5: ='H. Labour time'!D5*'G. Wages'!$D4 -> #DIV/0! | E5: ='H. Labour time'!G5*'G. Wages'!$D4 -> #DIV/0! | F5: ='H. Labour time'!H5*'G. Wages'!$D4 -> #DIV/0! | G5: ='H. Labour time'!I5*'G. Wages'!$D4 -> #DIV/0! | H5: ='H. Labour time'!J5*'G. Wages'!$D4 -> #DIV/0! | I5: ='H. Labour time'!K5*'G. Wages'!$D4 -> #DIV/0! | J5: =SUM(B5:I5) -> #DIV/0!
A6: [Add if needed] | B6: ='H. Labour time'!B6*'G. Wages'!$D5 -> #DIV/0! | C6: ='H. Labour time'!C6*'G. Wages'!$D5 -> #DIV/0! | D6: ='H. Labour time'!D6*'G. Wages'!$D5 -> #DIV/0! | E6: ='H. Labour time'!G6*'G. Wages'!$D5 -> #DIV/0! | F6: ='H. Labour time'!H6*'G. Wages'!$D5 -> #DIV/0! | G6: ='H. Labour time'!I6*'G. Wages'!$D5 -> #DIV/0! | H6: ='H. Labour time'!J6*'G. Wages'!$D5 -> #DIV/0! | I6: ='H. Labour time'!K6*'G. Wages'!$D5 -> #DIV/0! | J6: =SUM(B6:I6) -> #DIV/0!
A7: [Add if needed] | B7: ='H. Labour time'!B7*'G. Wages'!$D6 -> #DIV/0! | C7: ='H. Labour time'!C7*'G. Wages'!$D6 -> #DIV/0! | D7: ='H. Labour time'!D7*'G. Wages'!$D6 -> #DIV/0! | E7: ='H. Labour time'!G7*'G. Wages'!$D6 -> #DIV/0! | F7: ='H. Labour time'!H7*'G. Wages'!$D6 -> #DIV/0! | G7: ='H. Labour time'!I7*'G. Wages'!$D6 -> #DIV/0! | H7: ='H. Labour time'!J7*'G. Wages'!$D6 -> #DIV/0! | I7: ='H. Labour time'!K7*'G. Wages'!$D6 -> #DIV/0! | J7: =SUM(B7:I7) -> #DIV/0!
A8: [Add if needed] | B8: ='H. Labour time'!B8*'G. Wages'!$D7 -> #DIV/0! | C8: ='H. Labour time'!C8*'G. Wages'!$D7 -> #DIV/0! | D8: ='H. Labour time'!D8*'G. Wages'!$D7 -> #DIV/0! | E8: ='H. Labour time'!G8*'G. Wages'!$D7 -> #DIV/0! | F8: ='H. Labour time'!H8*'G. Wages'!$D7 -> #DIV/0! | G8: ='H. Labour time'!I8*'G. Wages'!$D7 -> #DIV/0! | H8: ='H. Labour time'!J8*'G. Wages'!$D7 -> #DIV/0! | I8: ='H. Labour time'!K8*'G. Wages'!$D7 -> #DIV/0! | J8: =SUM(B8:I8) -> #DIV/0!
A9: [Add if needed] | B9: ='H. Labour time'!B9*'G. Wages'!$D8 -> #DIV/0! | C9: ='H. Labour time'!C9*'G. Wages'!$D8 -> #DIV/0! | D9: ='H. Labour time'!D9*'G. Wages'!$D8 -> #DIV/0! | E9: ='H. Labour time'!G9*'G. Wages'!$D8 -> #DIV/0! | F9: ='H. Labour time'!H9*'G. Wages'!$D8 -> #DIV/0! | G9: ='H. Labour time'!I9*'G. Wages'!$D8 -> #DIV/0! | H9: ='H. Labour time'!J9*'G. Wages'!$D8 -> #DIV/0! | I9: ='H. Labour time'!K9*'G. Wages'!$D8 -> #DIV/0! | J9: =SUM(B9:I9) -> #DIV/0!
A10: [Add if needed] | B10: ='H. Labour time'!B10*'G. Wages'!$D9 -> #DIV/0! | C10: ='H. Labour time'!C10*'G. Wages'!$D9 -> #DIV/0! | D10: ='H. Labour time'!D10*'G. Wages'!$D9 -> #DIV/0! | E10: ='H. Labour time'!G10*'G. Wages'!$D9 -> #DIV/0! | F10: ='H. Labour time'!H10*'G. Wages'!$D9 -> #DIV/0! | G10: ='H. Labour time'!I10*'G. Wages'!$D9 -> #DIV/0! | H10: ='H. Labour time'!J10*'G. Wages'!$D9 -> #DIV/0! | I10: ='H. Labour time'!K10*'G. Wages'!$D9 -> #DIV/0! | J10: =SUM(B10:I10) -> #DIV/0!
A11: [Add if needed] | B11: ='H. Labour time'!B11*'G. Wages'!$D10 -> #DIV/0! | C11: ='H. Labour time'!C11*'G. Wages'!$D10 -> #DIV/0! | D11: ='H. Labour time'!D11*'G. Wages'!$D10 -> #DIV/0! | E11: ='H. Labour time'!G11*'G. Wages'!$D10 -> #DIV/0! | F11: ='H. Labour time'!H11*'G. Wages'!$D10 -> #DIV/0! | G11: ='H. Labour time'!I11*'G. Wages'!$D10 -> #DIV/0! | H11: ='H. Labour time'!J11*'G. Wages'!$D10 -> #DIV/0! | I11: ='H. Labour time'!K11*'G. Wages'!$D10 -> #DIV/0! | J11: =SUM(B11:I11) -> #DIV/0!
A12: [Add if needed] | B12: ='H. Labour time'!B12*'G. Wages'!$D11 -> #DIV/0! | C12: ='H. Labour time'!C12*'G. Wages'!$D11 -> #DIV/0! | D12: ='H. Labour time'!D12*'G. Wages'!$D11 -> #DIV/0! | E12: ='H. Labour time'!G12*'G. Wages'!$D11 -> #DIV/0! | F12: ='H. Labour time'!H12*'G. Wages'!$D11 -> #DIV/0! | G12: ='H. Labour time'!I12*'G. Wages'!$D11 -> #DIV/0! | H12: ='H. Labour time'!J12*'G. Wages'!$D11 -> #DIV/0! | I12: ='H. Labour time'!K12*'G. Wages'!$D11 -> #DIV/0! | J12: =SUM(B12:I12) -> #DIV/0!
A13: [Add if needed] | B13: ='H. Labour time'!B13*'G. Wages'!$D12 -> #DIV/0! | C13: ='H. Labour time'!C13*'G. Wages'!$D12 -> #DIV/0! | D13: ='H. Labour time'!D13*'G. Wages'!$D12 -> #DIV/0! | E13: ='H. Labour time'!G13*'G. Wages'!$D12 -> #DIV/0! | F13: ='H. Labour time'!H13*'G. Wages'!$D12 -> #DIV/0! | G13: ='H. Labour time'!I13*'G. Wages'!$D12 -> #DIV/0! | H13: ='H. Labour time'!J13*'G. Wages'!$D12 -> #DIV/0! | I13: ='H. Labour time'!K13*'G. Wages'!$D12 -> #DIV/0! | J13: =SUM(B13:I13) -> #DIV/0!
A14: [Add if needed] | B14: ='H. Labour time'!B14*'G. Wages'!$D13 -> #DIV/0! | C14: ='H. Labour time'!C14*'G. Wages'!$D13 -> #DIV/0! | D14: ='H. Labour time'!D14*'G. Wages'!$D13 -> #DIV/0! | E14: ='H. Labour time'!G14*'G. Wages'!$D13 -> #DIV/0! | F14: ='H. Labour time'!H14*'G. Wages'!$D13 -> #DIV/0! | G14: ='H. Labour time'!I14*'G. Wages'!$D13 -> #DIV/0! | H14: ='H. Labour time'!J14*'G. Wages'!$D13 -> #DIV/0! | I14: ='H. Labour time'!K14*'G. Wages'!$D13 -> #DIV/0! | J14: =SUM(B14:I14) -> #DIV/0!
A15: [Add if needed] | B15: ='H. Labour time'!B15*'G. Wages'!$D14 -> #DIV/0! | C15: ='H. Labour time'!C15*'G. Wages'!$D14 -> #DIV/0! | D15: ='H. Labour time'!D15*'G. Wages'!$D14 -> #DIV/0! | E15: ='H. Labour time'!G15*'G. Wages'!$D14 -> #DIV/0! | F15: ='H. Labour time'!H15*'G. Wages'!$D14 -> #DIV/0! | G15: ='H. Labour time'!I15*'G. Wages'!$D14 -> #DIV/0! | H15: ='H. Labour time'!J15*'G. Wages'!$D14 -> #DIV/0! | I15: ='H. Labour time'!K15*'G. Wages'!$D14 -> #DIV/0! | J15: =SUM(B15:I15) -> #DIV/0!
A16: [Add if needed] | B16: ='H. Labour time'!B16*'G. Wages'!$D15 -> #DIV/0! | C16: ='H. Labour time'!C16*'G. Wages'!$D15 -> #DIV/0! | D16: ='H. Labour time'!D16*'G. Wages'!$D15 -> #DIV/0! | E16: ='H. Labour time'!G16*'G. Wages'!$D15 -> #DIV/0! | F16: ='H. Labour time'!H16*'G. Wages'!$D15 -> #DIV/0! | G16: ='H. Labour time'!I16*'G. Wages'!$D15 -> #DIV/0! | H16: ='H. Labour time'!J16*'G. Wages'!$D15 -> #DIV/0! | I16: ='H. Labour time'!K16*'G. Wages'!$D15 -> #DIV/0! | J16: =SUM(B16:I16) -> #DIV/0!
A17: TOTAL PER STAGE (USD) | B17: =SUM(B3:B16) -> #DIV/0! | C17: =SUM(C3:C16) -> #DIV/0! | D17: =SUM(D3:D16) -> #DIV/0! | E17: =SUM(E3:E16) -> #DIV/0! | F17: =SUM(F3:F16) -> #DIV/0! | G17: =SUM(G3:G16) -> #DIV/0! | H17: =SUM(H3:H16) -> #DIV/0! | I17: =SUM(I3:I16) -> #DIV/0! | J17: =SUM(J3:J16) -> #DIV/0!
A19: * if error message appears, it means your monitoring hours exceed the product of number of farmers and number of monitoring visits

Sheet J. Per diem allowance
B1: Days of travel needed per stage, per job role
A2: Job role | B2: Trial preparation | C2: Training field agents | D2: Seed distribution | E2: Total number of farm visits * | F2: Farms visited per day | G2: Monitoring ** | H2: Data collection | I2: Yield measurement | J2: Product Evaluation | K2: Farmer Feedback | L2: Travel days (single day) | M2: Travel allowance costs | N2: TOTAL DAYS | O2: Per diem costs | P2: Travel time costs
A3: {=_xlfn._xlws.FILTER('G. Wages'!A2:A15, 'G. Wages'!A2:A15<> "")} -> [Add if needed] | G3: =IF(E3<='B. Trial dimensions'!$B$12*'B. Trial dimensions'!$B$9,E3/F3,"Number is too high") -> #DIV/0! | M3: ='G. Wages'!F2*L3 -> 0 | N3: =IFERROR(B3+C3+D3+G3+I3+J3+K3,"") | O3: =N3*'G. Wages'!E2 -> #VALUE! | P3: =M3+O3 -> #VALUE!
A4: [Add if needed] | G4: =IF(E4<='B. Trial dimensions'!$B$12*'B. Trial dimensions'!$B$9,E4/F4,"Number is too high") -> #DIV/0! | M4: ='G. Wages'!F3*L4 -> 0 | N4: =IFERROR(B4+C4+D4+G4+I4+J4+K4,"") | O4: =N4*'G. Wages'!E3 -> #VALUE! | P4: =M4+O4 -> #VALUE!
A5: [Add if needed] | G5: =IF(E5<='B. Trial dimensions'!$B$12*'B. Trial dimensions'!$B$9,E5/F5,"Number is too high") -> #DIV/0! | M5: ='G. Wages'!F4*L5 -> 0 | N5: =IFERROR(B5+C5+D5+G5+I5+J5+K5,"") | O5: =N5*'G. Wages'!E4 -> #VALUE! | P5: =M5+O5 -> #VALUE!
A6: [Add if needed] | G6: =IF(E6<='B. Trial dimensions'!$B$12*'B. Trial dimensions'!$B$9,E6/F6,"Number is too high") -> #DIV/0! | M6: ='G. Wages'!F5*L6 -> 0 | N6: =IFERROR(B6+C6+D6+G6+I6+J6+K6,"") | O6: =N6*'G. Wages'!E5 -> #VALUE! | P6: =M6+O6 -> #VALUE!
A7: [Add if needed] | G7: =IF(E7<='B. Trial dimensions'!$B$12*'B. Trial dimensions'!$B$9,E7/F7,"Number is too high") -> #DIV/0! | M7: ='G. Wages'!F6*L7 -> 0 | N7: =IFERROR(B7+C7+D7+G7+I7+J7+K7,"") | O7: =N7*'G. Wages'!E6 -> #VALUE! | P7: =M7+O7 -> #VALUE!
A8: [Add if needed] | G8: =IF(E8<='B. Trial dimensions'!$B$12*'B. Trial dimensions'!$B$9,E8/F8,"Number is too high") -> #DIV/0! | M8: ='G. Wages'!F7*L8 -> 0 | N8: =IFERROR(B8+C8+D8+G8+I8+J8+K8,"") | O8: =N8*'G. Wages'!E7 -> #VALUE! | P8: =M8+O8 -> #VALUE!
A9: [Add if needed] | G9: =IF(E9<='B. Trial dimensions'!$B$13*'B. Trial dimensions'!$B$9,E9/F9,"Number is too high") -> #DIV/0! | M9: ='G. Wages'!F8*L9 -> 0 | N9: =IFERROR(B9+C9+D9+G9+I9+J9+K9,"") | O9: =N9*'G. Wages'!E8 -> #VALUE! | P9: =M9+O9 -> #VALUE!
A10: [Add if needed] | G10: =IF(E10<='B. Trial dimensions'!$B$13*'B. Trial dimensions'!$B$9,E10/F10,"Number is too high") -> #DIV/0! | M10: ='G. Wages'!F9*L10 -> 0 | N10: =IFERROR(B10+C10+D10+G10+I10+J10+K10,"") | O10: =N10*'G. Wages'!E9 -> #VALUE! | P10: =M10+O10 -> #VALUE!
A11: [Add if needed] | G11: =IF(E11<='B. Trial dimensions'!$B$13*'B. Trial dimensions'!$B$9,E11/F11,"Number is too high") -> #DIV/0! | M11: ='G. Wages'!F10*L11 -> 0 | N11: =IFERROR(B11+C11+D11+G11+I11+J11+K11,"") | O11: =N11*'G. Wages'!E10 -> #VALUE! | P11: =M11+O11 -> #VALUE!
A12: [Add if needed] | G12: =IF(E12<='B. Trial dimensions'!$B$13*'B. Trial dimensions'!$B$9,E12/F12,"Number is too high") -> #DIV/0! | M12: ='G. Wages'!F11*L12 -> 0 | N12: =IFERROR(B12+C12+D12+G12+I12+J12+K12,"") | O12: =N12*'G. Wages'!E11 -> #VALUE! | P12: =M12+O12 -> #VALUE!
A13: [Add if needed] | G13: =IF(E13<='B. Trial dimensions'!$B$13*'B. Trial dimensions'!$B$9,E13/F13,"Number is too high") -> #DIV/0! | M13: ='G. Wages'!F12*L13 -> 0 | N13: =IFERROR(B13+C13+D13+G13+I13+J13+K13,"") | O13: =N13*'G. Wages'!E12 -> #VALUE! | P13: =M13+O13 -> #VALUE!
A14: [Add if needed] | G14: =IF(E14<='B. Trial dimensions'!$B$13*'B. Trial dimensions'!$B$9,E14/F14,"Number is too high") -> #DIV/0! | M14: ='G. Wages'!F13*L14 -> 0 | N14: =IFERROR(B14+C14+D14+G14+I14+J14+K14,"") | O14: =N14*'G. Wages'!E13 -> #VALUE! | P14: =M14+O14 -> #VALUE!
A15: [Add if needed] | G15: =IF(E15<='B. Trial dimensions'!$B$13*'B. Trial dimensions'!$B$9,E15/F15,"Number is too high") -> #DIV/0! | M15: ='G. Wages'!F14*L15 -> 0 | O15: =N15*'G. Wages'!E14 -> 0 | P15: =M15+O15 -> 0
A16: [Add if needed] | G16: =IF(E16<='B. Trial dimensions'!$B$13*'B. Trial dimensions'!$B$9,E16/F16,"Number is too high") -> #DIV/0! | M16: ='G. Wages'!F15*L16 -> 0 | O16: =N16*'G. Wages'!E15 -> 0 | P16: =M16+O16 -> 0
A17: TOTAL PER STAGE (DAYS) | B17: =SUM(B3:B16) -> 0 | C17: =SUM(C3:C16) -> 0 | D17: =SUM(D3:D16) -> 0 | E17: =SUM(E3:E16) -> 0 | F17: =SUM(F3:F16) -> 0 | G17: =SUM(G3:G16) -> #DIV/0! | H17: =SUM(H3:H16) -> 0 | I17: =SUM(I3:I16) -> 0 | ... P17: =SUM(P3:P16) -> #VALUE!
A18: TOTAL PER STAGE (DAYS) | B18: =B17/'B. Trial dimensions'!$B$19 -> #DIV/0! | C18: =C17/'B. Trial dimensions'!$B$19 -> #DIV/0! | D18: =D17/'B. Trial dimensions'!$B$19 -> #DIV/0! | E18: =E17/'B. Trial dimensions'!$B$19 -> #DIV/0! | F18: =F17/'B. Trial dimensions'!$B$19 -> #DIV/0! | G18: =G17/'B. Trial dimensions'!$B$19 -> #DIV/0! | H18: =H17/'B. Trial dimensions'!$B$19 -> #DIV/0! | I18: =I17/'B. Trial dimensions'!$B$19 -> #DIV/0! | ... P18: =P17/'B. Trial dimensions'!$B$19 -> #VALUE!
A20: * The number of farm visits should be calculated as follows: Total number of farms visited x Number of follow-up visits

Sheet K. Travel costs
A2: Labor type | C2: TOTAL DAYS | G2: Comments
A3: Scientist: Breeder | C3: =#REF!/8 -> #REF! | G3: Preparation: 8 meetings of 2h each + 2 hours of ClimMob project design
A4: Scientist: Associate Breeder | C4: =#REF!/8 -> #REF!
A5: Scientist: Research Officer | C5: =#REF!/8 -> #REF!
A6: Scientist: Research Assistant | C6: =#REF!/8 -> #REF!
A7: Non-scientist: Technician | C7: =#REF!/8 -> #REF!
A8: Non-scientist: Driver | C8: =#REF!/8 -> #REF!
A9: Extension Officer | C9: =#REF!/8 -> #REF!
A10: TOTAL PER STAGE | C10: =SUM(C3:C9) -> #REF!
A12: Stage | B12: Kilometers travelled | C12: Total fuel costs | D12: Number of travel days | E12: Total per diem costs | F12: Total travel costs | G12: Comments
A13: Trial preparation | C13: =B13*'E. Unit prices'!$D$25 -> 0 | D13: ='J. Per diem allowance'!$B$18 -> #DIV/0! | E13: ='B. Trial dimensions'!$B$20*D13 -> #DIV/0! | F13: =C13+E13 -> #DIV/0!
A14: Training of field agents and farmers | C14: =B14*'E. Unit prices'!$D$25 -> 0 | D14: ='J. Per diem allowance'!$C$18 -> #DIV/0! | E14: ='B. Trial dimensions'!$B$20*D14 -> #DIV/0! | F14: =C14+E14 -> #DIV/0!
A15: Seed distribution | C15: =B15*'E. Unit prices'!$D$25 -> 0 | D15: ='J. Per diem allowance'!$D$18 -> #DIV/0! | E15: ='B. Trial dimensions'!$B$20*D15 -> #DIV/0! | F15: =C15+E15 -> #DIV/0!
A16: Monitoring: Research | C16: =B16*'E. Unit prices'!$D$25 -> 0 | D16: ='J. Per diem allowance'!$G$18 -> #DIV/0! | E16: ='B. Trial dimensions'!$B$20*D16 -> #DIV/0! | F16: =C16+E16 -> #DIV/0!
A17: Monitoring: Extension | C17: =B17*'E. Unit prices'!$D$25 -> 0 | D17: ='J. Per diem allowance'!$G$18 -> #DIV/0! | E17: ='B. Trial dimensions'!$B$20*D17 -> #DIV/0! | F17: =C17+E17 -> #DIV/0!
A18: Data collection | C18: =B18*'E. Unit prices'!$D$25 -> 0 | D18: ='J. Per diem allowance'!$G$18 -> #DIV/0! | E18: ='B. Trial dimensions'!$B$20*D18 -> #DIV/0! | F18: =C18+E18 -> #DIV/0!
A19: Yield measurement | C19: =B19*'E. Unit prices'!$D$25 -> 0 | D19: ='J. Per diem allowance'!$I$18 -> #DIV/0! | E19: ='B. Trial dimensions'!$B$20*D19 -> #DIV/0! | F19: =C19+E19 -> #DIV/0!
A20: Product evaluation | C20: =B20*'E. Unit prices'!$D$25 -> 0 | D20: ='J. Per diem allowance'!$J$18 -> #DIV/0! | E20: ='B. Trial dimensions'!$B$20*D20 -> #DIV/0! | F20: =C20+E20 -> #DIV/0!
A21: Farmer feedback workshops | C21: =B21*'E. Unit prices'!$D$25 -> 0 | D21: ='J. Per diem allowance'!$K$18 -> #DIV/0! | E21: ='B. Trial dimensions'!$B$20*D21 -> #DIV/0! | F21: =C21+E21 -> #DIV/0!
A24: TOTAL PER STAGE | B24: =SUM(B13:B21) -> 0 | C24: =SUM(C13:C21) -> 0 | D24: =SUM(D13:D21) -> #DIV/0! | E24: =SUM(E13:E21) -> #DIV/0! | F24: =SUM(F13:F21) -> #DIV/0!

Sheet L. Call costs
B1: Minutes of phone calls needed per month per job role, per farmer/block
A2: Job role | B2: Number of staff | C2: Months of call bundles / staff | D2: Total cost | E2: Comments
A3: {=_xlfn._xlws.FILTER('G. Wages'!A2:A15, 'G. Wages'!A2:A15<>"")} -> [Add if needed] | D3: =B3*C3*'E. Unit prices'!$D$24 -> 0
A4: [Add if needed] | D4: =B4*C4*'E. Unit prices'!$D$24 -> 0
A5: [Add if needed] | D5: =B5*C5*'E. Unit prices'!$D$24 -> 0
A6: [Add if needed] | D6: =B6*C6*'E. Unit prices'!$D$24 -> 0
A7: [Add if needed] | D7: =B7*C7*'E. Unit prices'!$D$24 -> 0
A8: [Add if needed] | D8: =B8*C8*'E. Unit prices'!$D$24 -> 0
A9: [Add if needed] | D9: =B9*C9*'E. Unit prices'!$D$24 -> 0
A10: [Add if needed] | D10: =B10*C10*'E. Unit prices'!$D$24 -> 0
A11: [Add if needed] | D11: =B11*C11*'E. Unit prices'!$D$24 -> 0
A12: [Add if needed] | D12: =B12*C12*'E. Unit prices'!$D$24 -> 0
A13: [Add if needed] | D13: =B13*C13*'E. Unit prices'!$D$24 -> 0
A14: [Add if needed] | D14: =B14*C14*'E. Unit prices'!$D$24 -> 0
A15: [Add if needed] | D15: =B15*C15*'E. Unit prices'!$D$24 -> 0
A16: [Add if needed] | D16: =B16*C16*'E. Unit prices'!$D$24 -> 0
A17: TOTAL PER STAGE | B17: =SUM(B3:B14) -> 0 | C17: =SUM(C3:C14) -> 0 | D17: =SUM(D3:D14) -> 0
A19: *Use the International Telecommunication Union (ITU) ICT price baskets for your country accessed at: https://www.itu.int/en/ITU-D/Statistics/Dashboards/Pages/IPB.aspx
A20: *While on the page in the image below, select TABLES from the menu bar, the basket "Mobile data and voice low-consumption basket (70 min + 20 SMS + 500 MB), Price Measure "USD" and Year "Current year" and scroll to view information for your country.
A21: *Months of call bundles/ staff column C shows how many month bundles each role needs from planting to farmer feedback
A22: *Changing cell B1 to another country's value will automatically scale the total cost to the country's price level

Sheet M. Overview
A1: Item | B1: Whole trial | C1: Per block
A2: Materials | B2: ='F. Material costs'!D24 -> 0 | C2: ='F. Material costs'!D25 -> #DIV/0!
A3: Labor | B3: =SUM(B4:B17) -> #DIV/0! | C3: =B3/'B. Trial dimensions'!$B$9 -> #DIV/0!
A4: ='G. Wages'!A2 -> [Add if needed] | B4: ='G. Wages'!C2*'H. Labour time'!M3 -> #DIV/0! | C4: =B4/'B. Trial dimensions'!$B$9 -> #DIV/0!
A5: ='G. Wages'!A3 -> [Add if needed] | B5: ='G. Wages'!C3*'H. Labour time'!M4 -> #DIV/0! | C5: =B5/'B. Trial dimensions'!$B$9 -> #DIV/0!
A6: ='G. Wages'!A4 -> [Add if needed] | B6: ='G. Wages'!C4*'H. Labour time'!M5 -> #DIV/0! | C6: =B6/'B. Trial dimensions'!$B$9 -> #DIV/0!
A7: ='G. Wages'!A5 -> [Add if needed] | B7: ='G. Wages'!C5*'H. Labour time'!M6 -> #DIV/0! | C7: =B7/'B. Trial dimensions'!$B$9 -> #DIV/0!
A8: ='G. Wages'!A6 -> [Add if needed] | B8: ='G. Wages'!C6*'H. Labour time'!M7 -> #DIV/0! | C8: =B8/'B. Trial dimensions'!$B$9 -> #DIV/0!
A9: ='G. Wages'!A7 -> [Add if needed] | B9: ='G. Wages'!C7*'H. Labour time'!M8 -> #DIV/0! | C9: =B9/'B. Trial dimensions'!$B$9 -> #DIV/0!
A10: ='G. Wages'!A8 -> [Add if needed] | B10: ='G. Wages'!C8*'H. Labour time'!M9 -> #DIV/0! | C10: =B10/'B. Trial dimensions'!$B$9 -> #DIV/0!
A11: ='G. Wages'!A9 -> [Add if needed] | B11: ='G. Wages'!C9*'H. Labour time'!M10 -> #DIV/0! | C11: =B11/'B. Trial dimensions'!$B$9 -> #DIV/0!
A12: ='G. Wages'!A10 -> [Add if needed] | B12: ='G. Wages'!C10*'H. Labour time'!M11 -> #DIV/0! | C12: =B12/'B. Trial dimensions'!$B$9 -> #DIV/0!
A13: ='G. Wages'!A11 -> [Add if needed] | B13: ='G. Wages'!C11*'H. Labour time'!M12 -> #DIV/0! | C13: =B13/'B. Trial dimensions'!$B$9 -> #DIV/0!
A14: ='G. Wages'!A12 -> [Add if needed] | B14: ='G. Wages'!C12*'H. Labour time'!M13 -> #DIV/0! | C14: =B14/'B. Trial dimensions'!$B$9 -> #DIV/0!
A15: ='G. Wages'!A13 -> [Add if needed] | B15: ='G. Wages'!C13*'H. Labour time'!M14 -> #DIV/0! | C15: =B15/'B. Trial dimensions'!$B$9 -> #DIV/0!
... A17: ='G. Wages'!A15 -> [Add if needed] | B17: ='G. Wages'!C15*'H. Labour time'!M16 -> #DIV/0! | C17: =B17/'B. Trial dimensions'!$B$9 -> #DIV/0!
A18: Travel time | B18: =SUM(B19:B30) -> #VALUE! | C18: =B18/'B. Trial dimensions'!$B$9 -> #VALUE!
A19: ='J. Per diem allowance'!A3 -> [Add if needed] | B19: ='J. Per diem allowance'!O3 -> #VALUE! | C19: =B19/'B. Trial dimensions'!$B$9 -> #VALUE!
A20: ='J. Per diem allowance'!A4 -> [Add if needed] | B20: ='J. Per diem allowance'!O4 -> #VALUE! | C20: =B20/'B. Trial dimensions'!$B$9 -> #VALUE!
A21: ='J. Per diem allowance'!A5 -> [Add if needed] | B21: ='J. Per diem allowance'!O5 -> #VALUE! | C21: =B21/'B. Trial dimensions'!$B$9 -> #VALUE!
A22: ='J. Per diem allowance'!A6 -> [Add if needed] | B22: ='J. Per diem allowance'!O6 -> #VALUE! | C22: =B22/'B. Trial dimensions'!$B$9 -> #VALUE!
A23: ='J. Per diem allowance'!A7 -> [Add if needed] | B23: ='J. Per diem allowance'!O7 -> #VALUE! | C23: =B23/'B. Trial dimensions'!$B$9 -> #VALUE!
A24: ='J. Per diem allowance'!A8 -> [Add if needed] | B24: ='J. Per diem allowance'!O8 -> #VALUE! | C24: =B24/'B. Trial dimensions'!$B$9 -> #VALUE!
A25: ='J. Per diem allowance'!A9 -> [Add if needed] | B25: ='J. Per diem allowance'!O9 -> #VALUE! | C25: =B25/'B. Trial dimensions'!$B$9 -> #VALUE!
A26: ='J. Per diem allowance'!A10 -> [Add if needed] | B26: ='J. Per diem allowance'!O10 -> #VALUE! | C26: =B26/'B. Trial dimensions'!$B$9 -> #VALUE!
A27: ='J. Per diem allowance'!A11 -> [Add if needed] | B27: ='J. Per diem allowance'!O11 -> #VALUE! | C27: =B27/'B. Trial dimensions'!$B$9 -> #VALUE!
A28: ='J. Per diem allowance'!A12 -> [Add if needed] | B28: ='J. Per diem allowance'!O12 -> #VALUE! | C28: =B28/'B. Trial dimensions'!$B$9 -> #VALUE!
A29: ='J. Per diem allowance'!A13 -> [Add if needed] | B29: ='J. Per diem allowance'!O13 -> #VALUE! | C29: =B29/'B. Trial dimensions'!$B$9 -> #VALUE!
A30: ='J. Per diem allowance'!A14 -> [Add if needed] | B30: ='J. Per diem allowance'!O14 -> #VALUE! | C30: =B30/'B. Trial dimensions'!$B$9 -> #VALUE!
A31: Travel cost | B31: ='K. Travel costs'!F24 -> #DIV/0! | C31: =B31/'B. Trial dimensions'!$B$9 -> #DIV/0!
A32: ='K. Travel costs'!A13 -> Trial preparation | B32: ='K. Travel costs'!F13 -> #DIV/0! | C32: =B32/'B. Trial dimensions'!$B$9 -> #DIV/0!
A33: Training field agents | B33: ='K. Travel costs'!F14 -> #DIV/0! | C33: =B33/'B. Trial dimensions'!$B$9 -> #DIV/0!
A34: ='K. Travel costs'!A15 -> Seed distribution | B34: ='K. Travel costs'!F15 -> #DIV/0! | C34: =B34/'B. Trial dimensions'!$B$9 -> #DIV/0!
A35: ='K. Travel costs'!A16 -> Monitoring: Research | B35: ='K. Travel costs'!F16 -> #DIV/0! | C35: =B35/'B. Trial dimensions'!$B$9 -> #DIV/0!
A36: ='K. Travel costs'!A19 -> Yield measurement | B36: ='K. Travel costs'!F19 -> #DIV/0! | C36: =B36/'B. Trial dimensions'!$B$9 -> #DIV/0!
A37: ='K. Travel costs'!A20 -> Product evaluation | B37: ='K. Travel costs'!F20 -> #DIV/0! | C37: =B37/'B. Trial dimensions'!$B$9 -> #DIV/0!
A38: Farmer feedback | B38: ='K. Travel costs'!F21 -> #DIV/0! | C38: =B38/'B. Trial dimensions'!$B$9 -> #DIV/0!
A39: Phone calls | B39: =SUM(B40:B53) -> 0 | C39: =B39/'B. Trial dimensions'!$B$9 -> #DIV/0!
A40: ='L. Call costs'!A3 -> [Add if needed] | B40: ='L. Call costs'!D3 -> 0 | C40: =B40/'B. Trial dimensions'!$B$9 -> #DIV/0!
A41: ='L. Call costs'!A4 -> [Add if needed] | B41: ='L. Call costs'!D4 -> 0 | C41: =B41/'B. Trial dimensions'!$B$9 -> #DIV/0!
...

Sheet N. Sensitivity analysis
A1: TRICOT COSTING SENSITIVITY ANALYSIS DASHBOARD
A3: Cost driver | B3: Baseline Value | C3: % Adjusted | D3: Adjusted Value | E3: Change (%) | F3: Estimated Cost Impact (USD) | G3: Comments
A4: Number of Farmers | B4: ='B. Trial dimensions'!B9 -> 0 | D4: =B4*(1+C4) -> 0 | E4: =((D4-B4)/B4) -> #DIV/0! | F4: ='M. Overview'!$B$54*E4 -> #DIV/0!
A5: Monitoring Visits (Research) | B5: ='B. Trial dimensions'!B12 -> 0 | D5: =B5*(1+C5) -> 0 | E5: =((D5-B5)/B5) -> #DIV/0! | F5: ='M. Overview'!$B$54*E5 -> #DIV/0!
A6: Monitoring Visits (Extension) | B6: ='B. Trial dimensions'!B13 -> 0 | D6: =B6*(1+C6) -> 0 | E6: =((D6-B6)/B6) -> #DIV/0! | F6: ='M. Overview'!$B$54*E6 -> #DIV/0!
A7: Travel Cost | B7: ='M. Overview'!B31 -> #DIV/0! | D7: =B7*(1+C7) -> #DIV/0! | E7: =((D7-B7)/B7) -> #DIV/0! | F7: ='M. Overview'!$B$54*E7 -> #DIV/0!
A8: Labour Cost | B8: ='M. Overview'!B3 -> #DIV/0! | D8: =B8*(1+C8) -> #DIV/0! | E8: =((D8-B8)/B8) -> #DIV/0! | F8: ='M. Overview'!$B$54*E8 -> #DIV/0!
A9: Material Costs | B9: ='M. Overview'!B2 -> 0 | D9: =B9*(1+C9) -> 0 | E9: =((D9-B9)/B9) -> #DIV/0! | F9: ='M. Overview'!$B$54*E9 -> #DIV/0!
A11: *Manually adjust the % in the adjusted value (column C) and sign +/- for adjusted value increase or decrease

Sheet O. Scenario analysis
A1: Scenario Analysis for Tricot Costing
A2: This table presents hypothetical adjustments to cost drivers and their projected impact on total cost.
A4: Scenario | B4: Change | C4: Cost driver | D4: No. of Farmers | E4: Monitoring Visits (Avg) | F4: Fuel Cost Index % | G4: Labour Cost Index % | H4: Material Cost Index % | I4: FarmerFactor | J4: VisitFactor | K4: FuelFactor | L4: LabourFactor | M4: MaterialFactor | N4: Estimated Total Cost (USD) | O4: % change in Total costs | P4: Comments
A5: Baseline | C5: Baseline | I5: 1 | J5: 1 | K5: 1 | L5: 1 | M5: 1 | N5: ='M. Overview'!$B$54 -> #DIV/0! | O5: =(N5-$N$5)/$N$5% -> #DIV/0!
A6: Scenario A | C6: Farmers | D6: =D5+(B6*D5) -> 0 | E6: =E5 -> 0 | F6: =$F$5 -> 0 | G6: =$G$5 -> 0 | H6: =$H$5 -> 0 | I6: =D6/$D$5 -> #DIV/0! | J6: =E6/$E$5 -> #DIV/0! | K6: =F6/$F$5 -> #DIV/0! | L6: =G6/$G$5 -> #DIV/0! | M6: =H6/$H$5 -> #DIV/0! | N6: ='M. Overview'!$B$2*M6*I6+('M. Overview'!$B$3+'M. Overview'!$B$18)*L6*I6*J6+'M. Overview'!$B$31*K6*J6+'M. Overview'!$B$39*I6 -> #DIV/0! | O6: =(N6-$N$5)/$N$5 -> #DIV/0!
A7: Scenario B | C7: Monitoring | D7: =$D$5 -> 0 | E7: =E6+(B7*E6) -> 0 | F7: =$F$5 -> 0 | G7: =$G$5 -> 0 | H7: =$H$5 -> 0 | I7: =D7/$D$5 -> #DIV/0! | J7: =E7/$E$5 -> #DIV/0! | K7: =F7/$F$5 -> #DIV/0! | L7: =G7/$G$5 -> #DIV/0! | M7: =H7/$H$5 -> #DIV/0! | N7: ='M. Overview'!$B$2*M7*I7+('M. Overview'!$B$3+'M. Overview'!$B$18)*L7*I7*J7+'M. Overview'!$B$31*K7*J7+'M. Overview'!$B$39*I7 -> #DIV/0! | O7: =(N7-$N$5)/$N$5 -> #DIV/0!
A8: Scenario C | C8: Fuel cost index | D8: =$D$5 -> 0 | E8: =$E$5 -> 0 | F8: =F5+(B8*F5) -> 0 | G8: =$G$5 -> 0 | H8: =$H$5 -> 0 | I8: =D8/$D$5 -> #DIV/0! | J8: =E8/$E$5 -> #DIV/0! | K8: =F8/$F$5 -> #DIV/0! | L8: =G8/$G$5 -> #DIV/0! | M8: =H8/$H$5 -> #DIV/0! | N8: ='M. Overview'!$B$2*M8*I8+('M. Overview'!$B$3+'M. Overview'!$B$18)*L8*I8*J8+'M. Overview'!$B$31*K8*J8+'M. Overview'!$B$39*I8 -> #DIV/0! | O8: =(N8-$N$5)/$N$5 -> #DIV/0!
A9: Scenario D | C9: Labor cost index | D9: =$D$5 -> 0 | E9: =$E$5 -> 0 | F9: =$F$5 -> 0 | G9: =G5+(B9*G5) -> 0 | H9: =$H$5 -> 0 | I9: =D9/$D$5 -> #DIV/0! | J9: =E9/$E$5 -> #DIV/0! | K9: =F9/$F$5 -> #DIV/0! | L9: =G9/$G$5 -> #DIV/0! | M9: =H9/$H$5 -> #DIV/0! | N9: ='M. Overview'!$B$2*M9*I9+('M. Overview'!$B$3+'M. Overview'!$B$18)*L9*I9*J9+'M. Overview'!$B$31*K9*J9+'M. Overview'!$B$39*I9 -> #DIV/0! | O9: =(N9-$N$5)/$N$5 -> #DIV/0!
A10: Scenario E | C10: Material cost index | D10: =$D$5 -> 0 | E10: =$E$5 -> 0 | F10: =$F$5 -> 0 | G10: =$G$5 -> 0 | H10: =H5+(B10*H5) -> 0 | I10: =D10/$D$5 -> #DIV/0! | J10: =E10/$E$5 -> #DIV/0! | K10: =F10/$F$5 -> #DIV/0! | L10: =G10/$G$5 -> #DIV/0! | M10: =H10/$H$5 -> #DIV/0! | N10: ='M. Overview'!$B$2*M10*I10+('M. Overview'!$B$3+'M. Overview'!$B$18)*L10*I10*J10+'M. Overview'!$B$31*K10*J10+'M. Overview'!$B$39*I10 -> #DIV/0! | O10: =(N10-$N$5)/$N$5 -> #DIV/0!
A11: Scenario F | C11: All of the above | D11: =D6 -> 0 | E11: =E7 -> 0 | F11: =F8 -> 0 | G11: =G9 -> 0 | H11: =H10 -> 0 | I11: =D11/$D$5 -> #DIV/0! | J11: =E11/$E$5 -> #DIV/0! | K11: =F11/$F$5 -> #DIV/0! | L11: =G11/$G$5 -> #DIV/0! | M11: =H11/$H$5 -> #DIV/0! | N11: ='M. Overview'!$B$2*M11*I11+('M. Overview'!$B$3+'M. Overview'!$B$18)*L11*I11*J11+'M. Overview'!$B$31*K11*J11+'M. Overview'!$B$39*I11 -> #DIV/0! | O11: =(N11-$N$5)/$N$5 -> #DIV/0!
A13: *Manually adjust the input index values (%)
